 '2025-07-31T09:17:38.573Z'}
172.31.104.194 - - [31/Jul/2025 09:17:38] "POST /api/log-error HTTP/1.1" 200 -
2025-07-31 09:17:38,659 - ErrorHandlers - ERROR - [logger] Frontend Error: Failed to initialize FloorplanManager: | Context: {'frontend_error': True, 'level': 'ERROR', 'error': None, 'stack': None, 'context': {}, 'url': 'https://772be468-3bfd-436e-8a95-f0c335b68d5a-00-350xnchcym1u0.sisko.replit.dev/site-inspector?project_id=9?project=9', 'userAgent': 'Mozilla/5.0 (Macintosh; Intel Mac OS X 10_15_7) AppleWebKit/537.36 (KHTML, like Gecko) Chrome/138.0.0.0 Safari/537.36', 'timestamp': '2025-07-31T09:17:38.572Z'}
172.31.104.194 - - [31/Jul/2025 09:17:38] "POST /api/log-error HTTP/1.1" 200 -
2025-07-31 09:17:44,908 - engineroom - INFO - [logger] Site inspector request - URL: http://772be468-3bfd-436e-8a95-f0c335b68d5a-00-350xnchcym1u0.sisko.replit.dev/site-inspector?project_id=9?project=9
2025-07-31 09:17:44,908 - engineroom - INFO - [logger] Site inspector request - Args: {'project_id': '9?project=9'}
2025-07-31 09:17:44,908 - engineroom - INFO - [logger] Site inspector request - Project ID: 9?project=9
2025-07-31 09:17:44,908 - engineroom - INFO - [logger] Cleaned malformed project ID early: 9
2025-07-31 09:17:44,909 - engineroom - ERROR - [logger] Database initialization failed: disk I/O error
2025-07-31 09:17:44,909 - engineroom - ERROR - [logger] Failed to retrieve project data: Failed to initialize database: disk I/O error
2025-07-31 09:17:44,909 - engineroom - INFO - [logger] No site data in session, loading site inspector for new polygon creation | Context: {'session_keys': ['current_project_address', 'current_project_id', 'current_project_name', 'user', 'user_timezone'], 'user_agent': 'Mozilla/5.0 (Macintosh; Intel Mac OS X 10_15_7) AppleWebKit/537.36 (KHTML, like Gecko) Chrome/138.0.0.0 Safari/537.36', 'referer': 'https://772be468-3bfd-436e-8a95-f0c335b68d5a-00-350xnchcym1u0.sisko.replit.dev/__replco/workspace_iframe.html?initialPath=%2Fsite-inspector%3Fproject_id%3D9%3Fproject%3D9&id=%3Ardr%3A'}
2025-07-31 09:17:44,909 - engineroom - INFO - [logger] Processing site inspector request | Context: {'site_data_keys': ['area', 'area_m2', 'type', 'coordinates', 'center', 'ready_for_new_polygon'], 'has_coordinates': False, 'coordinate_count': 0, 'has_center': False, 'area': 0}
2025-07-31 09:17:44,910 - engineroom - WARNING - [logger] Site data validation failed: ['No coordinates provided', 'Center point is required', 'Area must be positive, got: 0', 'Area too small (min 1 m²): 0']
2025-07-31 09:17:44,910 - engineroom - WARNING - [logger] Site data validation warnings (non-blocking): Site data validation issues: No coordinates provided; Center point is required; Area must be positive, got: 0; Area too small (min 1 m²): 0
2025-07-31 09:17:44,910 - engineroom - INFO - [logger] Processing site inspector for area: 0 m²
2025-07-31 09:17:44,910 - engineroom - INFO - [logger] GradientService - Cache hit: Returning cached gradient data
2025-07-31 09:17:44,910 - engineroom - INFO - [logger] Gradient data calculated successfully
2025-07-31 09:17:44,910 - engineroom - WARNING - [logger] No council name available for requirements lookup
172.31.104.194 - - [31/Jul/2025 09:17:44] "GET /site-inspector?project_id=9?project=9 HTTP/1.1" 200 -
172.31.104.194 - - [31/Jul/2025 09:17:45] "GET /static/styles.css HTTP/1.1" 304 -
172.31.104.194 - - [31/Jul/2025 09:17:45] "GET /static/js/adam-chat-widget.js HTTP/1.1" 304 -
172.31.104.194 - - [31/Jul/2025 09:17:45] "GET /static/js/core.js HTTP/1.1" 304 -
172.31.104.194 - - [31/Jul/2025 09:17:45] "GET /static/js/opencv-processor.js HTTP/1.1" 304 -
172.31.104.194 - - [31/Jul/2025 09:17:45] "GET /static/js/site-inspector/site-boundary-manager.js HTTP/1.1" 304 -
172.31.104.194 - - [31/Jul/2025 09:17:45] "GET /static/js/floorplan-manager.js HTTP/1.1" 304 -
172.31.104.194 - - [31/Jul/2025 09:17:45] "GET /static/js/site-inspector/property-setbacks-manager.js HTTP/1.1" 304 -
172.31.104.194 - - [31/Jul/2025 09:17:45] "GET /static/css/adam-chat-widget.css HTTP/1.1" 304 -
172.31.104.194 - - [31/Jul/2025 09:17:45] "GET /static/js/site-inspector/map-features-manager.js HTTP/1.1" 304 -
172.31.104.194 - - [31/Jul/2025 09:17:45] "GET /static/js/site-inspector/site-inspector-core.js HTTP/1.1" 304 -
172.31.104.194 - - [31/Jul/2025 09:17:45] "GET /static/js/site-inspector/ui-panel-manager.js HTTP/1.1" 304 -
2025-07-31 09:17:46,187 - engineroom - INFO - [logger] Getting conversations for user ID: 3
2025-07-31 09:17:46,188 - engineroom - ERROR - [logger] Failed to get user conversations: disk I/O error
2025-07-31 09:17:46,188 - engineroom - INFO - [logger] Retrieved 0 conversations
172.31.104.194 - - [31/Jul/2025 09:17:46] "GET /api/conversations?limit=1&agent=ADAM HTTP/1.1" 200 -
2025-07-31 09:17:46,278 - engineroom - ERROR - [logger] Error getting project address: disk I/O error
172.31.104.194 - - [31/Jul/2025 09:17:46] "GET /api/project-address?project_id=9 HTTP/1.1" 500 -
2025-07-31 09:17:46,461 - ErrorHandlers - ERROR - [logger] Frontend Error: ⚠️ Project address could not be loaded, proceeding with default location | Context: {'frontend_error': True, 'level': 'WARN', 'error': None, 'stack': None, 'context': None, 'url': 'https://772be468-3bfd-436e-8a95-f0c335b68d5a-00-350xnchcym1u0.sisko.replit.dev/site-inspector?project_id=9?project=9', 'userAgent': 'Mozilla/5.0 (Macintosh; Intel Mac OS X 10_15_7) AppleWebKit/537.36 (KHTML, like Gecko) Chrome/138.0.0.0 Safari/537.36', 'timestamp': '2025-07-31T09:17:46.365Z'}
172.31.104.194 - - [31/Jul/2025 09:17:46] "POST /api/log-error HTTP/1.1" 200 -
2025-07-31 09:17:46,462 - ErrorHandlers - ERROR - [logger] Frontend Error: API request failed with status 500: Internal Server Error | Context: {'frontend_error': True, 'level': 'ERROR', 'error': None, 'stack': None, 'context': None, 'url': 'https://772be468-3bfd-436e-8a95-f0c335b68d5a-00-350xnchcym1u0.sisko.replit.dev/site-inspector?project_id=9?project=9', 'userAgent': 'Mozilla/5.0 (Macintosh; Intel Mac OS X 10_15_7) AppleWebKit/537.36 (KHTML, like Gecko) Chrome/138.0.0.0 Safari/537.36', 'timestamp': '2025-07-31T09:17:46.365Z'}
172.31.104.194 - - [31/Jul/2025 09:17:46] "POST /api/log-error HTTP/1.1" 200 -
172.31.104.194 - - [31/Jul/2025 09:17:46] "GET /api/mapbox-token HTTP/1.1" 200 -
2025-07-31 09:17:46,872 - engineroom - INFO - [logger] Getting project snapshot for project 9, type: None
2025-07-31 09:17:46,872 - engineroom - ERROR - [logger] Failed to get project snapshot: disk I/O error
2025-07-31 09:17:46,872 - engineroom - INFO - [logger] Snapshot result: None
172.31.104.194 - - [31/Jul/2025 09:17:46] "GET /api/project/9/snapshot HTTP/1.1" 404 -
2025-07-31 09:17:47,048 - engineroom - INFO - [logger] Getting project snapshot for project 9, type: None
2025-07-31 09:17:47,048 - engineroom - ERROR - [logger] Failed to get project snapshot: disk I/O error
2025-07-31 09:17:47,048 - engineroom - INFO - [logger] Snapshot result: None
172.31.104.194 - - [31/Jul/2025 09:17:47] "GET /api/project/9/snapshot HTTP/1.1" 404 -
2025-07-31 09:17:47,228 - ErrorHandlers - ERROR - [logger] Frontend Error: Failed to initialize MapFeaturesManager: | Context: {'frontend_error': True, 'level': 'ERROR', 'error': None, 'stack': None, 'context': {}, 'url': 'https://772be468-3bfd-436e-8a95-f0c335b68d5a-00-350xnchcym1u0.sisko.replit.dev/site-inspector?project_id=9?project=9', 'userAgent': 'Mozilla/5.0 (Macintosh; Intel Mac OS X 10_15_7) AppleWebKit/537.36 (KHTML, like Gecko) Chrome/138.0.0.0 Safari/537.36', 'timestamp': '2025-07-31T09:17:47.140Z'}
172.31.104.194 - - [31/Jul/2025 09:17:47] "POST /api/log-error HTTP/1.1" 200 -
2025-07-31 09:17:47,233 - ErrorHandlers - ERROR - [logger] Frontend Error: Failed to initialize FloorplanManager: | Context: {'frontend_error': True, 'level': 'ERROR', 'error': None, 'stack': None, 'context': {}, 'url': 'https://772be468-3bfd-436e-8a95-f0c335b68d5a-00-350xnchcym1u0.sisko.replit.dev/site-inspector?project_id=9?project=9', 'userAgent': 'Mozilla/5.0 (Macintosh; Intel Mac OS X 10_15_7) AppleWebKit/537.36 (KHTML, like Gecko) Chrome/138.0.0.0 Safari/537.36', 'timestamp': '2025-07-31T09:17:47.140Z'}
172.31.104.194 - - [31/Jul/2025 09:17:47] "POST /api/log-error HTTP/1.1" 200 -
2025-07-31 09:17:52,317 - engineroom - ERROR - [logger] Error getting project by ID: disk I/O error
172.31.104.194 - - [31/Jul/2025 09:17:52] "GET /project/9 HTTP/1.1" 404 -
2025-07-31 09:17:57,327 - engineroom - INFO - [logger] Base project route accessed, redirecting to dashboard
172.31.104.194 - - [31/Jul/2025 09:17:57] "GET /project/ HTTP/1.1" 302 -
2025-07-31 09:17:57,524 - engineroom - ERROR - [logger] Failed to get user profile for dashboard: disk I/O error
2025-07-31 09:17:57,524 - engineroom - INFO - [logger] Dashboard accessed by user: tomo
172.31.104.194 - - [31/Jul/2025 09:17:57] "GET /dashboard HTTP/1.1" 200 -
172.31.104.194 - - [31/Jul/2025 09:17:57] "GET /static/css/adam-chat-widget.css HTTP/1.1" 304 -
172.31.104.194 - - [31/Jul/2025 09:17:57] "GET /static/css/dashboard.css HTTP/1.1" 304 -
172.31.104.194 - - [31/Jul/2025 09:17:57] "GET /static/app.js HTTP/1.1" 304 -
172.31.104.194 - - [31/Jul/2025 09:17:57] "GET /static/js/core.js HTTP/1.1" 304 -
172.31.104.194 - - [31/Jul/2025 09:17:57] "GET /static/js/adam-chat-widget.js HTTP/1.1" 304 -
172.31.104.194 - - [31/Jul/2025 09:17:57] "GET /static/js/dashboard-config.js HTTP/1.1" 304 -
172.31.104.194 - - [31/Jul/2025 09:17:58] "GET /static/js/dashboard-utils.js HTTP/1.1" 304 -
172.31.104.194 - - [31/Jul/2025 09:17:58] "GET /static/js/dashboard.js HTTP/1.1" 304 -
172.31.104.194 - - [31/Jul/2025 09:17:58] "GET /static/js/dashboard-modal.js HTTP/1.1" 304 -
172.31.104.194 - - [31/Jul/2025 09:17:58] "GET /static/js/dashboard-table.js HTTP/1.1" 304 -
2025-07-31 09:17:58,872 - engineroom - ERROR - [logger] Error getting user projects: disk I/O error
172.31.104.194 - - [31/Jul/2025 09:17:58] "GET /api/get-user-projects HTTP/1.1" 200 -
2025-07-31 09:17:58,878 - engineroom - INFO - [logger] Getting conversations for user ID: 3
2025-07-31 09:17:58,881 - engineroom - ERROR - [logger] Failed to get user conversations: disk I/O error
2025-07-31 09:17:58,881 - engineroom - INFO - [logger] Retrieved 0 conversations
2025-07-31 09:17:58,882 - engineroom - ERROR - [logger] Get team name error: disk I/O error
172.31.104.194 - - [31/Jul/2025 09:17:58] "GET /api/conversations?limit=1&agent=ADAM HTTP/1.1" 200 -
172.31.104.194 - - [31/Jul/2025 09:17:58] "GET /conversations HTTP/1.1" 200 -
172.31.104.194 - - [31/Jul/2025 09:17:58] "GET /api/get-team-name HTTP/1.1" 500 -
2025-07-31 09:17:59,055 - engineroom - ERROR - [logger] Error getting user projects: disk I/O error
172.31.104.194 - - [31/Jul/2025 09:17:59] "GET /api/get-user-projects HTTP/1.1" 200 -
2025-07-31 09:17:59,057 - engineroom - ERROR - [logger] Get team name error: disk I/O error
172.31.104.194 - - [31/Jul/2025 09:17:59] "GET /api/get-team-name HTTP/1.1" 500 -
2025-07-31 09:18:08,909 - engineroom - ERROR - [logger] Database initialization failed: disk I/O error
[2025-07-31 09:18:08,909] ERROR in app: Exception on / [GET]
Traceback (most recent call last):
  File "/home/runner/workspace/database.py", line 72, in _ensure_tables_exist
    with self.db.get_cursor() as cursor:
  File "/nix/store/7d088dip86hlzri9sk0h78b63yfmx0a0-python3-3.11.13/lib/python3.11/contextlib.py", line 137, in __enter__
    return next(self.gen)
           ^^^^^^^^^^^^^^
  File "/home/runner/workspace/database.py", line 49, in get_cursor
    conn = self.get_connection()
           ^^^^^^^^^^^^^^^^^^^^^
  File "/home/runner/workspace/database.py", line 36, in get_connection
    self._local.connection.execute("PRAGMA journal_mode=WAL")
sqlite3.OperationalError: disk I/O error

During handling of the above exception, another exception occurred:

Traceback (most recent call last):
  File "/home/runner/workspace/.pythonlibs/lib/python3.11/site-packages/flask/app.py", line 1511, in wsgi_app
    response = self.full_dispatch_request()
               ^^^^^^^^^^^^^^^^^^^^^^^^^^^^
  File "/home/runner/workspace/.pythonlibs/lib/python3.11/site-packages/flask/app.py", line 919, in full_dispatch_request
    rv = self.handle_user_exception(e)
         ^^^^^^^^^^^^^^^^^^^^^^^^^^^^^
  File "/home/runner/workspace/.pythonlibs/lib/python3.11/site-packages/flask/app.py", line 917, in full_dispatch_request
    rv = self.dispatch_request()
         ^^^^^^^^^^^^^^^^^^^^^^^
  File "/home/runner/workspace/.pythonlibs/lib/python3.11/site-packages/flask/app.py", line 902, in dispatch_request
    return self.ensure_sync(self.view_functions[rule.endpoint])(**view_args)  # type: ignore[no-any-return]
           ^^^^^^^^^^^^^^^^^^^^^^^^^^^^^^^^^^^^^^^^^^^^^^^^^^^^^^^^^^^^^^^^^
  File "/home/runner/workspace/routes/page_routes.py", line 63, in handle_index
    auth_handler = AuthRoutes()
                   ^^^^^^^^^^^^
  File "/home/runner/workspace/routes/auth_routes.py", line 13, in __init__
    self.db_manager = DatabaseManager()
                      ^^^^^^^^^^^^^^^^^
  File "/home/runner/workspace/database.py", line 67, in __init__
    self._ensure_tables_exist()
  File "/home/runner/workspace/database.py", line 91, in _ensure_tables_exist
    raise DatabaseError(f"Failed to initialize database: {e}")
database.DatabaseError: Failed to initialize database: disk I/O error
2025-07-31 09:18:09,148 - ErrorHandlers - ERROR - [logger] Internal server error | Context: {'error_type': 'InternalServerError', 'error_message': '500 Internal Server Error: The server encountered an internal error and was unable to complete your request. Either the server is overloaded or there is an error in the application.', 'traceback': 'Traceback (most recent call last):\n  File "/home/runner/workspace/database.py", line 72, in _ensure_tables_exist\n    with self.db.get_cursor() as cursor:\n  File "/nix/store/7d088dip86hlzri9sk0h78b63yfmx0a0-python3-3.11.13/lib/python3.11/contextlib.py", line 137, in __enter__\n    return next(self.gen)\n           ^^^^^^^^^^^^^^\n  File "/home/runner/workspace/database.py", line 49, in get_cursor\n    conn = self.get_connection()\n           ^^^^^^^^^^^^^^^^^^^^^\n  File "/home/runner/workspace/database.py", line 36, in get_connection\n    self._local.connection.execute("PRAGMA journal_mode=WAL")\nsqlite3.OperationalError: disk I/O error\n\nDuring handling of the above exception, another exception occurred:\n\nTraceback (most recent call last):\n  File "/home/runner/workspace/.pythonlibs/lib/python3.11/site-packages/flask/app.py", line 1511, in wsgi_app\n    response = self.full_dispatch_request()\n               ^^^^^^^^^^^^^^^^^^^^^^^^^^^^\n  File "/home/runner/workspace/.pythonlibs/lib/python3.11/site-packages/flask/app.py", line 919, in full_dispatch_request\n    rv = self.handle_user_exception(e)\n         ^^^^^^^^^^^^^^^^^^^^^^^^^^^^^\n  File "/home/runner/workspace/.pythonlibs/lib/python3.11/site-packages/flask/app.py", line 917, in full_dispatch_request\n    rv = self.dispatch_request()\n         ^^^^^^^^^^^^^^^^^^^^^^^\n  File "/home/runner/workspace/.pythonlibs/lib/python3.11/site-packages/flask/app.py", line 902, in dispatch_request\n    return self.ensure_sync(self.view_functions[rule.endpoint])(**view_args)  # type: ignore[no-any-return]\n           ^^^^^^^^^^^^^^^^^^^^^^^^^^^^^^^^^^^^^^^^^^^^^^^^^^^^^^^^^^^^^^^^^\n  File "/home/runner/workspace/routes/page_routes.py", line 63, in handle_index\n    auth_handler = AuthRoutes()\n                   ^^^^^^^^^^^^\n  File "/home/runner/workspace/routes/auth_routes.py", line 13, in __init__\n    self.db_manager = DatabaseManager()\n                      ^^^^^^^^^^^^^^^^^\n  File "/home/runner/workspace/database.py", line 67, in __init__\n    self._ensure_tables_exist()\n  File "/home/runner/workspace/database.py", line 91, in _ensure_tables_exist\n    raise DatabaseError(f"Failed to initialize database: {e}")\ndatabase.DatabaseError: Failed to initialize database: disk I/O error\n'}
172.31.104.194 - - [31/Jul/2025 09:18:09] "GET / HTTP/1.1" 500 -
2025-07-31 09:18:23,124 - engineroom - ERROR - [logger] Database initialization failed: disk I/O error
[2025-07-31 09:18:23,124] ERROR in app: Exception on / [GET]
Traceback (most recent call last):
  File "/home/runner/workspace/database.py", line 72, in _ensure_tables_exist
    with self.db.get_cursor() as cursor:
  File "/nix/store/7d088dip86hlzri9sk0h78b63yfmx0a0-python3-3.11.13/lib/python3.11/contextlib.py", line 137, in __enter__
    return next(self.gen)
           ^^^^^^^^^^^^^^
  File "/home/runner/workspace/database.py", line 49, in get_cursor
    conn = self.get_connection()
           ^^^^^^^^^^^^^^^^^^^^^
  File "/home/runner/workspace/database.py", line 36, in get_connection
    self._local.connection.execute("PRAGMA journal_mode=WAL")
sqlite3.OperationalError: disk I/O error

During handling of the above exception, another exception occurred:

Traceback (most recent call last):
  File "/home/runner/workspace/.pythonlibs/lib/python3.11/site-packages/flask/app.py", line 1511, in wsgi_app
    response = self.full_dispatch_request()
               ^^^^^^^^^^^^^^^^^^^^^^^^^^^^
  File "/home/runner/workspace/.pythonlibs/lib/python3.11/site-packages/flask/app.py", line 919, in full_dispatch_request
    rv = self.handle_user_exception(e)
         ^^^^^^^^^^^^^^^^^^^^^^^^^^^^^
  File "/home/runner/workspace/.pythonlibs/lib/python3.11/site-packages/flask/app.py", line 917, in full_dispatch_request
    rv = self.dispatch_request()
         ^^^^^^^^^^^^^^^^^^^^^^^
  File "/home/runner/workspace/.pythonlibs/lib/python3.11/site-packages/flask/app.py", line 902, in dispatch_request
    return self.ensure_sync(self.view_functions[rule.endpoint])(**view_args)  # type: ignore[no-any-return]
           ^^^^^^^^^^^^^^^^^^^^^^^^^^^^^^^^^^^^^^^^^^^^^^^^^^^^^^^^^^^^^^^^^
  File "/home/runner/workspace/routes/page_routes.py", line 63, in handle_index
    auth_handler = AuthRoutes()
                   ^^^^^^^^^^^^
  File "/home/runner/workspace/routes/auth_routes.py", line 13, in __init__
    self.db_manager = DatabaseManager()
                      ^^^^^^^^^^^^^^^^^
  File "/home/runner/workspace/database.py", line 67, in __init__
    self._ensure_tables_exist()
  File "/home/runner/workspace/database.py", line 91, in _ensure_tables_exist
    raise DatabaseError(f"Failed to initialize database: {e}")
database.DatabaseError: Failed to initialize database: disk I/O error
2025-07-31 09:18:23,127 - ErrorHandlers - ERROR - [logger] Internal server error | Context: {'error_type': 'InternalServerError', 'error_message': '500 Internal Server Error: The server encountered an internal error and was unable to complete your request. Either the server is overloaded or there is an error in the application.', 'traceback': 'Traceback (most recent call last):\n  File "/home/runner/workspace/database.py", line 72, in _ensure_tables_exist\n    with self.db.get_cursor() as cursor:\n  File "/nix/store/7d088dip86hlzri9sk0h78b63yfmx0a0-python3-3.11.13/lib/python3.11/contextlib.py", line 137, in __enter__\n    return next(self.gen)\n           ^^^^^^^^^^^^^^\n  File "/home/runner/workspace/database.py", line 49, in get_cursor\n    conn = self.get_connection()\n           ^^^^^^^^^^^^^^^^^^^^^\n  File "/home/runner/workspace/database.py", line 36, in get_connection\n    self._local.connection.execute("PRAGMA journal_mode=WAL")\nsqlite3.OperationalError: disk I/O error\n\nDuring handling of the above exception, another exception occurred:\n\nTraceback (most recent call last):\n  File "/home/runner/workspace/.pythonlibs/lib/python3.11/site-packages/flask/app.py", line 1511, in wsgi_app\n    response = self.full_dispatch_request()\n               ^^^^^^^^^^^^^^^^^^^^^^^^^^^^\n  File "/home/runner/workspace/.pythonlibs/lib/python3.11/site-packages/flask/app.py", line 919, in full_dispatch_request\n    rv = self.handle_user_exception(e)\n         ^^^^^^^^^^^^^^^^^^^^^^^^^^^^^\n  File "/home/runner/workspace/.pythonlibs/lib/python3.11/site-packages/flask/app.py", line 917, in full_dispatch_request\n    rv = self.dispatch_request()\n         ^^^^^^^^^^^^^^^^^^^^^^^\n  File "/home/runner/workspace/.pythonlibs/lib/python3.11/site-packages/flask/app.py", line 902, in dispatch_request\n    return self.ensure_sync(self.view_functions[rule.endpoint])(**view_args)  # type: ignore[no-any-return]\n           ^^^^^^^^^^^^^^^^^^^^^^^^^^^^^^^^^^^^^^^^^^^^^^^^^^^^^^^^^^^^^^^^^\n  File "/home/runner/workspace/routes/page_routes.py", line 63, in handle_index\n    auth_handler = AuthRoutes()\n                   ^^^^^^^^^^^^\n  File "/home/runner/workspace/routes/auth_routes.py", line 13, in __init__\n    self.db_manager = DatabaseManager()\n                      ^^^^^^^^^^^^^^^^^\n  File "/home/runner/workspace/database.py", line 67, in __init__\n    self._ensure_tables_exist()\n  File "/home/runner/workspace/database.py", line 91, in _ensure_tables_exist\n    raise DatabaseError(f"Failed to initialize database: {e}")\ndatabase.DatabaseError: Failed to initialize database: disk I/O error\n'}
172.31.104.194 - - [31/Jul/2025 09:18:23] "GET / HTTP/1.1" 500 -